<?xml version='1.0'?>
<sdf version='1.4'>
  <model name="my_robot">
        <static>false</static>
<link name='chassis'>
            <pose>0 0 .26 0 0 0</pose>

            <collision name='collision'>
            <geometry>
            <box>
            <size>1.2954 .5715 .127</size>
            </box>
            </geometry>
            </collision>

            <visual name='visual'>
            <geometry>
            <box>
            <size>1.2954 .5715 .127</size>
            </box>
            </geometry>
            </visual>
<?Wheel 1_Front?>
 	    <collision name='caster_collision'>
            <pose>-.4953 0 -.1651 0 0 0</pose>
            <geometry>
            <sphere>
            <radius>.0889</radius>
            </sphere>
            </geometry>

            <surface>
            <friction>
            <ode>
            <mu>0</mu>
            <mu2>0</mu2>
            <slip1>1.0</slip1>
            <slip2>1.0</slip2>
            </ode>
            </friction>
            </surface>
            </collision>

            <visual name='caster_visual'>
            <pose>-.4953 0 -.1651 0 0 0</pose>
            <geometry>
            <sphere>
            <radius>.0889</radius>
            </sphere>
            </geometry>
            </visual>

<?Wheel 2_ Back ?>

	    <collision name='caster_collision'>
            <pose>.4953 0 -.1651 0 0 0</pose>
            <geometry>
            <sphere>
            <radius>.0889</radius>
            </sphere>
            </geometry>

            <surface>
            <friction>
            <ode>
            <mu>0</mu>
            <mu2>0</mu2>
            <slip1>1.0</slip1>
            <slip2>1.0</slip2>
            </ode>
            </friction>
            </surface>
            </collision>

            <visual name='caster_visual2'>
            <pose>.4953 0 -.1651 0 0 0</pose>
            <geometry>
            <sphere>
            <radius>.0889</radius>
            </sphere>
            </geometry>
            </visual>




          </link>

<?Wheel 3_ Middle ?>

	   <link name="left_wheel">
           <pose>0.0 0.23495 0.0889 0 1.5707 1.5707</pose>
           <collision name="collision">
           <geometry>
           <cylinder>
           <radius>.0889</radius>
           <length>.0508</length>
           </cylinder>
           </geometry>
           </collision>
           <visual name="visual">
           <geometry>
           <cylinder>
           <radius>.0889</radius>
           <length>.0508</length>
           </cylinder>
           </geometry>
           </visual>
           </link>

<?Wheel 4_ Middle ?>

	   <link name="right_wheel">
           <pose>0.0 -0.23495 0.0889 0 1.5707 1.5707</pose>
           <collision name="collision">
           <geometry>
           <cylinder>
           <radius>.0889</radius>
           <length>.0508</length>
           </cylinder>
           </geometry>
           </collision>
           <visual name="visual">
           <geometry>
           <cylinder>
           <radius>.0889</radius>
           <length>.0508</length>
           </cylinder>
           </geometry>
           </visual>
           </link>

<?Adding the wheel joints?>

           <joint type="revolute" name="left_wheel_hinge">
           <pose>0 0 -0.03 0 0 0</pose>
           <child>left_wheel</child>
           <parent>chassis</parent>
           <axis>
           <xyz>0 1 0</xyz>
           </axis>
           </joint>
 
           <joint type="revolute" name="right_wheel_hinge">
           <pose>0 0 0.03 0 0 0</pose>
           <child>right_wheel</child>
           <parent>chassis</parent>
           <axis>
           <xyz>0 1 0</xyz>
           </axis>
           </joint>

  </model>
</sdf>
          
